Workbook

Sheet Games
A1: Name | B1: Sales | C1: Series | D1: Release | E1: Genre | F1: Developer | G1: Publisher | H1: PlayerCount
A2: PlayerUnknown's Battlegrounds | B2: 42 | D2: 43070 | E2: Battle royale | F2: PUBG Studios | G2: Krafton | H2: 2.3
A3: Minecraft | B3: 33 | C3: Minecraft | D3: 40848 | E3: Sandbox, survival | F3: Mojang Studios | G3: Mojang Studios | H3: 1.5
A4: Diablo III | B4: 20 | C4: Diablo | D4: 41030 | E4: Action role-playing | F4: Blizzard Entertainment | G4: Blizzard Entertainment | H4: 1
A5: Garry's Mod | B5: 20 | D5: 39022 | E5: Sandbox | F5: Facepunch Studios | G5: Valve | H5: 1.1
A6: Terraria | B6: 17.2 | D6: 40664 | E6: Action-adventure | F6: Re-Logic | G6: Re-Logic | H6: 0.98
A7: World of Warcraft | B7: 14 | C7: Warcraft | D7: 38292 | E7: MMORPG | F7: Blizzard Entertainment | G7: Blizzard Entertainment
A8: Half-Life 2 | B8: 12 | C8: Half-Life | D8: 38292 | E8: First-person shooter | F8: Valve | G8: Valve (digital)
A9: The Witcher 3: Wild Hunt | B9: 12 | C9: The Witcher | D9: 42125 | E9: Action role-playing | F9: CD Projekt Red | G9: CD Projekt
A10: StarCraft | B10: 11 | C10: StarCraft | D10: 35855 | E10: Real-time strategy | F10: Blizzard Entertainment | G10: Blizzard Entertainment
A11: The Sims | B11: 11 | C11: The Sims | D11: 36557 | E11: Life simulation | F11: Maxis | G11: Electronic Arts
A12: Fall Guys | B12: 10 | D12: 44044 | E12: Battle royale | F12: Mediatonic | G12: Devolver Digital
A13: RollerCoaster Tycoon 3 | B13: 10 | C13: RollerCoaster Tycoon | D13: 38261 | E13: Construction and management simulation | F13: Frontier Developments | G13: Atari, Inc. (Windows)
A14: Half-Life | B14: 9 | C14: Half-Life | D14: 36100 | E14: First-person shooter | F14: Valve | G14: Sierra Entertainment
A15: Rust | B15: 9 | D15: 43132 | E15: Survival | F15: Facepunch Studios | G15: Facepunch Studios
A16: Civilization V | B16: 8 | C16: Civilization | D16: 40422 | E16: Turn-based strategy, 4X | F16: Firaxis Games | G16: 2K Games & Aspyr
A17: The Sims 3 | B17: 7 | C17: The Sims | D17: 39965 | E17: Life simulation | F17: Maxis | G17: Electronic Arts
A18: Euro Truck Simulator 2 | B18: 6.5 | C18: Truck Simulator | D18: 41183 | E18: Vehicle simulation | F18: SCS Software | G18: SCS Software
A19: Guild Wars | B19: 6 | C19: Guild Wars | D19: 38443 | E19: MMORPG | F19: ArenaNet | G19: NCsoft
A20: StarCraft II: Wings of Liberty | B20: 6 | C20: StarCraft | D20: 40360 | E20: Real-time strategy | F20: Blizzard Entertainment | G20: Blizzard Entertainment
A21: The Sims 2 | B21: 6 | C21: The Sims | D21: 38231 | E21: Life simulation | F21: Maxis | G21: Electronic Arts
A22: Valheim | B22: 6 | D22: 44228 | E22: Survival | F22: Iron Gate | G22: Coffee Stain Publishing
A23: ARMA 3 | B23: 5.5 | C23: ARMA | D23: 41518 | E23: Tactical shooter | F23: Bohemia Interactive | G23: Bohemia Interactive
A24: Last Ninja 2 | B24: 5.5 | C24: The Last Ninja | D24: 32356 | E24: Action-adventure | F24: System 3 | G24: Activision
A25: Cities: Skylines | B25: 5 | D25: 42064 | E25: City-building | F25: Colossal Order | G25: Paradox Interactive
A26: Guild Wars 2 | B26: 5 | C26: Guild Wars | D26: 41122 | E26: MMORPG | F26: ArenaNet | G26: NCsoft
A27: SimCity 3000 | B27: 5 | C27: SimCity | D27: 36161 | E27: City-building | F27: Maxis | G27: Electronic Arts
A28: The Forest | B28: 5 | D28: 43191 | E28: Survival | F28: Endnight Games | G28: Endnight Games
A29: Cyberpunk 2077 | B29: 4.5 | D29: 44166 | E29: Action role-playing | F29: CD Projekt Red | G29: CD Projekt
A30: DayZ | B30: 4 | D30: 41609 | E30: Survival | F30: Bohemia Interactive | G30: Bohemia Interactive
A31: Diablo II | B31: 4 | C31: Diablo | D31: 36678 | E31: Action role-playing | F31: Blizzard North | G31: Blizzard Entertainment
A32: Populous | B32: 4 | C32: Populous | D32: 32660 | E32: God game | F32: Bullfrog Productions | G32: Electronic Arts
A33: RollerCoaster Tycoon | B33: 4 | C33: RollerCoaster Tycoon | D33: 36220 | E33: Construction and management simulation | F33: Chris Sawyer | G33: MicroProse Software
A34: The Last Ninja | B34: 4 | C34: The Last Ninja | D34: 38504 | E34: Action-adventure | F34: System 3 | G34: Activision
A35: Warhammer 40,000: Dawn of War (including expansions) | B35: 4 | C35: Warhammer | D35: 38231 | E35: Real-time strategy | F35: Relic Entertainment | G35: THQ
A36: Where in the World Is Carmen Sandiego? | B36: 4 | C36: Carmen Sandiego | D36: 31199 | E36: Educational | F36: Broderbund | G36: Broderbund
A37: Dark Souls | B37: 3.6 | C37: Dark Souls | D37: 41122 | E37: Action role-playing | F37: FromSoftware | G37: Namco Bandai Games
A38: Dark Souls III | B38: 3.3 | C38: Dark Souls | D38: 42461 | E38: Action role-playing | F38: FromSoftware | G38: Bandai Namco Entertainment
A39: Age of Empires | B39: 3 | C39: Age of Empires | D39: 35704 | E39: Real-time strategy | F39: Ensemble Studios | G39: Microsoft
A40: Civilization IV | B40: 3 | C40: Civilization | D40: 38626 | E40: Turn-based strategy, 4X | F40: Firaxis Games | G40: 2K Games & Aspyr
...

Sheet Pub
A1: 1 | B1: Krafton
A2: 2 | B2: Mojang Studios
A3: 3 | B3: Blizzard Entertainment
A4: 4 | B4: Valve
A5: 5 | B5: Re-Logic
A6: 6 | B6: Valve (digital)
A7: 7 | B7: CD Projekt
A8: 8 | B8: Electronic Arts
A9: 9 | B9: Devolver Digital
A10: 10 | B10: Atari, Inc. (Windows)
A11: 11 | B11: Sierra Entertainment
A12: 12 | B12: Facepunch Studios
... A96: 96 | B96: Blue Fang Games

Sheet Dev
A1: 1 | B1: PUBG Studios | J1: 1
A2: 2 | B2: Mojang Studios | J2: =_xlfn.XLOOKUP(K2, Pub!B:B, Pub!A:A) -> 0
A3: 3 | B3: Blizzard Entertainment
A4: 4 | B4: Facepunch Studios
A5: 5 | B5: Re-Logic
A6: 6 | B6: Valve
A7: 7 | B7: CD Projekt Red
A8: 8 | B8: Maxis
A9: 9 | B9: Mediatonic
A10: 10 | B10: Frontier Developments
A11: 11 | B11: Firaxis Games
A12: 12 | B12: SCS Software
A13: 13 | B13: ArenaNet
A14: 14 | B14: Iron Gate
... A109: 109 | B109: Microsoft

Sheet Sheet2
A1: 1 | B1: PUBG Studios | C1: 42 | E1: 43070 | F1: 1 | G1: Battle royale | H1: 1 | I1: PUBG Studios | J1: 1 | K1: Krafton
A2: 2 | B2: Mojang Studios | C2: 33 | D2: Minecraft | E2: 40848 | F2: 2 | G2: Sandbox, survival | H2: 2 | I2: Mojang Studios | J2: =_xlfn.XLOOKUP(K2, Pub!B:B, Pub!A:A) -> 2 | K2: Mojang Studios
A3: 3 | B3: Blizzard Entertainment | C3: 20 | D3: Diablo | E3: 41030 | F3: 3 | G3: Action role-playing | H3: 3 | I3: Blizzard Entertainment | J3: =_xlfn.XLOOKUP(K3, Pub!B:B, Pub!A:A) -> 3 | K3: Blizzard Entertainment
A4: 4 | B4: Facepunch Studios | C4: 20 | E4: 39022 | F4: 4 | G4: Sandbox | H4: 4 | I4: Facepunch Studios | J4: =_xlfn.XLOOKUP(K4, Pub!B:B, Pub!A:A) -> 4 | K4: Valve
A5: 5 | B5: Re-Logic | C5: 17.2 | E5: 40664 | F5: 5 | G5: Action-adventure | H5: 5 | I5: Re-Logic | J5: =_xlfn.XLOOKUP(K5, Pub!B:B, Pub!A:A) -> 5 | K5: Re-Logic
A6: 6 | B6: Valve | C6: 14 | D6: Warcraft | E6: 38292 | F6: 6 | G6: MMORPG | H6: 3 | I6: Blizzard Entertainment | J6: =_xlfn.XLOOKUP(K6, Pub!B:B, Pub!A:A) -> 3 | K6: Blizzard Entertainment
A7: 7 | B7: CD Projekt Red | C7: 12 | D7: Half-Life | E7: 38292 | F7: 7 | G7: First-person shooter | H7: 6 | I7: Valve | J7: =_xlfn.XLOOKUP(K7, Pub!B:B, Pub!A:A) -> 6 | K7: Valve (digital)
A8: 8 | B8: Maxis | C8: 12 | D8: The Witcher | E8: 42125 | F8: 3 | G8: Action role-playing | H8: 7 | I8: CD Projekt Red | J8: =_xlfn.XLOOKUP(K8, Pub!B:B, Pub!A:A) -> 7 | K8: CD Projekt
A9: 9 | B9: Mediatonic | C9: 11 | D9: StarCraft | E9: 35855 | F9: 8 | G9: Real-time strategy | H9: 3 | I9: Blizzard Entertainment | J9: =_xlfn.XLOOKUP(K9, Pub!B:B, Pub!A:A) -> 3 | K9: Blizzard Entertainment
A10: 10 | B10: Frontier Developments | C10: 11 | D10: The Sims | E10: 36557 | F10: 9 | G10: Life simulation | H10: 8 | I10: Maxis | J10: =_xlfn.XLOOKUP(K10, Pub!B:B, Pub!A:A) -> 8 | K10: Electronic Arts
A11: 11 | B11: Firaxis Games | C11: 10 | E11: 44044 | F11: 1 | G11: Battle royale | H11: 9 | I11: Mediatonic | J11: =_xlfn.XLOOKUP(K11, Pub!B:B, Pub!A:A) -> 9 | K11: Devolver Digital
A12: 12 | B12: SCS Software | C12: 10 | D12: RollerCoaster Tycoon | E12: 38261 | F12: 10 | G12: Construction and management simulation | H12: 10 | I12: Frontier Developments | J12: =_xlfn.XLOOKUP(K12, Pub!B:B, Pub!A:A) -> 10 | K12: Atari, Inc. (Windows)
A13: 13 | B13: ArenaNet | C13: 9 | D13: Half-Life | E13: 36100 | F13: 7 | G13: First-person shooter | H13: 6 | I13: Valve | J13: =_xlfn.XLOOKUP(K13, Pub!B:B, Pub!A:A) -> 11 | K13: Sierra Entertainment
A14: 14 | B14: Iron Gate | C14: 9 | E14: 43132 | F14: 11 | G14: Survival | H14: 4 | I14: Facepunch Studios | J14: =_xlfn.XLOOKUP(K14, Pub!B:B, Pub!A:A) -> 12 | K14: Facepunch Studios
A15: 15 | B15: Bohemia Interactive | C15: 8 | D15: Civilization | E15: 40422 | F15: 12 | G15: Turn-based strategy, 4X | H15: 11 | I15: Firaxis Games | J15: =_xlfn.XLOOKUP(K15, Pub!B:B, Pub!A:A) -> 13 | K15: 2K Games & Aspyr
A16: 16 | B16: System 3 | C16: 7 | D16: The Sims | E16: 39965 | F16: 9 | G16: Life simulation | H16: 8 | I16: Maxis | J16: =_xlfn.XLOOKUP(K16, Pub!B:B, Pub!A:A) -> 8 | K16: Electronic Arts
A17: 17 | B17: Colossal Order | C17: 6.5 | D17: Truck Simulator | E17: 41183 | F17: 13 | G17: Vehicle simulation | H17: 12 | I17: SCS Software | J17: =_xlfn.XLOOKUP(K17, Pub!B:B, Pub!A:A) -> 14 | K17: SCS Software
A18: 18 | B18: Endnight Games | C18: 6 | D18: Guild Wars | E18: 38443 | F18: 6 | G18: MMORPG | H18: 13 | I18: ArenaNet | J18: =_xlfn.XLOOKUP(K18, Pub!B:B, Pub!A:A) -> 15 | K18: NCsoft
A19: 19 | B19: Blizzard North | C19: 6 | D19: StarCraft | E19: 40360 | F19: 8 | G19: Real-time strategy | H19: 3 | I19: Blizzard Entertainment | J19: =_xlfn.XLOOKUP(K19, Pub!B:B, Pub!A:A) -> 3 | K19: Blizzard Entertainment
A20: 20 | B20: Bullfrog Productions | C20: 6 | D20: The Sims | E20: 38231 | F20: 9 | G20: Life simulation | H20: 8 | I20: Maxis | J20: =_xlfn.XLOOKUP(K20, Pub!B:B, Pub!A:A) -> 8 | K20: Electronic Arts
A21: 21 | B21: Chris Sawyer | C21: 6 | E21: 44228 | F21: 11 | G21: Survival | H21: 14 | I21: Iron Gate | J21: =_xlfn.XLOOKUP(K21, Pub!B:B, Pub!A:A) -> 16 | K21: Coffee Stain Publishing
A22: 22 | B22: Relic Entertainment | C22: 5.5 | D22: ARMA | E22: 41518 | F22: 14 | G22: Tactical shooter | H22: 15 | I22: Bohemia Interactive | J22: =_xlfn.XLOOKUP(K22, Pub!B:B, Pub!A:A) -> 17 | K22: Bohemia Interactive
A23: 23 | B23: Broderbund | C23: 5.5 | D23: The Last Ninja | E23: 32356 | F23: 5 | G23: Action-adventure | H23: 16 | I23: System 3 | J23: =_xlfn.XLOOKUP(K23, Pub!B:B, Pub!A:A) -> 18 | K23: Activision
A24: 24 | B24: FromSoftware | C24: 5 | E24: 42064 | F24: 15 | G24: City-building | H24: 17 | I24: Colossal Order | J24: =_xlfn.XLOOKUP(K24, Pub!B:B, Pub!A:A) -> 19 | K24: Paradox Interactive
A25: 25 | B25: Ensemble Studios | C25: 5 | D25: Guild Wars | E25: 41122 | F25: 6 | G25: MMORPG | H25: 13 | I25: ArenaNet | J25: =_xlfn.XLOOKUP(K25, Pub!B:B, Pub!A:A) -> 15 | K25: NCsoft
A26: 26 | B26: Westwood Studios | C26: 5 | D26: SimCity | E26: 36161 | F26: 15 | G26: City-building | H26: 8 | I26: Maxis | J26: =_xlfn.XLOOKUP(K26, Pub!B:B, Pub!A:A) -> 8 | K26: Electronic Arts
A27: 27 | B27: Crytek | C27: 5 | E27: 43191 | F27: 11 | G27: Survival | H27: 18 | I27: Endnight Games | J27: =_xlfn.XLOOKUP(K27, Pub!B:B, Pub!A:A) -> 20 | K27: Endnight Games
A28: 28 | B28: Verant Interactive | C28: 4.5 | E28: 44166 | F28: 3 | G28: Action role-playing | H28: 7 | I28: CD Projekt Red | J28: =_xlfn.XLOOKUP(K28, Pub!B:B, Pub!A:A) -> 7 | K28: CD Projekt
A29: 29 | B29: Dontnod Entertainment | C29: 4 | E29: 41609 | F29: 11 | G29: Survival | H29: 15 | I29: Bohemia Interactive | J29: =_xlfn.XLOOKUP(K29, Pub!B:B, Pub!A:A) -> 17 | K29: Bohemia Interactive
A30: 30 | B30: Impressions Game | C30: 4 | D30: Diablo | E30: 36678 | F30: 3 | G30: Action role-playing | H30: 19 | I30: Blizzard North | J30: =_xlfn.XLOOKUP(K30, Pub!B:B, Pub!A:A) -> 3 | K30: Blizzard Entertainment
A31: 31 | B31: Wube Software | C31: 4 | D31: Populous | E31: 32660 | F31: 16 | G31: God game | H31: 20 | I31: Bullfrog Productions | J31: =_xlfn.XLOOKUP(K31, Pub!B:B, Pub!A:A) -> 8 | K31: Electronic Arts
A32: 32 | B32: Cyan | C32: 4 | D32: RollerCoaster Tycoon | E32: 36220 | F32: 10 | G32: Construction and management simulation | H32: 21 | I32: Chris Sawyer | J32: =_xlfn.XLOOKUP(K32, Pub!B:B, Pub!A:A) -> 21 | K32: MicroProse Software
A33: 33 | B33: Square | C33: 4 | D33: The Last Ninja | E33: 38504 | F33: 5 | G33: Action-adventure | H33: 16 | I33: System 3 | J33: =_xlfn.XLOOKUP(K33, Pub!B:B, Pub!A:A) -> 18 | K33: Activision
A34: 34 | B34: The Fun Pimps | C34: 4 | D34: Warhammer | E34: 38231 | F34: 8 | G34: Real-time strategy | H34: 22 | I34: Relic Entertainment | J34: =_xlfn.XLOOKUP(K34, Pub!B:B, Pub!A:A) -> 22 | K34: THQ
A35: 35 | B35: Max Design | C35: 4 | D35: Carmen Sandiego | E35: 31199 | F35: 17 | G35: Educational | H35: 23 | I35: Broderbund | J35: =_xlfn.XLOOKUP(K35, Pub!B:B, Pub!A:A) -> 23 | K35: Broderbund
A36: 36 | B36: BioWare | C36: 3.6 | D36: Dark Souls | E36: 41122 | F36: 3 | G36: Action role-playing | H36: 24 | I36: FromSoftware | J36: =_xlfn.XLOOKUP(K36, Pub!B:B, Pub!A:A) -> 24 | K36: Namco Bandai Games
A37: 37 | B37: EA DICE | C37: 3.3 | D37: Dark Souls | E37: 42461 | F37: 3 | G37: Action role-playing | H37: 24 | I37: FromSoftware | J37: =_xlfn.XLOOKUP(K37, Pub!B:B, Pub!A:A) -> 25 | K37: Bandai Namco Entertainment
A38: 38 | B38: Lionhead Studios | C38: 3 | D38: Age of Empires | E38: 35704 | F38: 8 | G38: Real-time strategy | H38: 25 | I38: Ensemble Studios | J38: =_xlfn.XLOOKUP(K38, Pub!B:B, Pub!A:A) -> 26 | K38: Microsoft
A39: 39 | B39: GSC Game World | C39: 3 | D39: Civilization | E39: 38626 | F39: 12 | G39: Turn-based strategy, 4X | H39: 11 | I39: Firaxis Games | J39: =_xlfn.XLOOKUP(K39, Pub!B:B, Pub!A:A) -> 13 | K39: 2K Games & Aspyr
A40: 40 | B40: id Software | C40: 3 | D40: Command & Conquer | E40: 34912 | F40: 8 | G40: Real-time strategy | H40: 26 | I40: Westwood Studios | J40: =_xlfn.XLOOKUP(K40, Pub!B:B, Pub!A:A) -> 27 | K40: Virgin Interactive
...

Sheet Video game dataset
A1: Name | B1: Genre | C1: Release | D1: Sales
A2: PlayerUnknown's Battlegrounds | B2: Battle royale | C2: 43070 | D2: 42
A3: Minecraft | B3: Sandbox, survival | C3: 40848 | D3: 33
A4: Diablo III | B4: Action role-playing | C4: 41030 | D4: 20
A5: Garry's Mod | B5: Sandbox | C5: 39022 | D5: 20
A6: Terraria | B6: Action-adventure | C6: 40664 | D6: 17.2
A7: World of Warcraft | B7: MMORPG | C7: 38292 | D7: 14
A8: Half-Life 2 | B8: First-person shooter | C8: 38292 | D8: 12
A9: The Witcher 3: Wild Hunt | B9: Action role-playing | C9: 42125 | D9: 12
A10: StarCraft | B10: Real-time strategy | C10: 35855 | D10: 11
A11: The Sims | B11: Life simulation | C11: 36557 | D11: 11
A12: Fall Guys | B12: Battle royale | C12: 44044 | D12: 10
A13: RollerCoaster Tycoon 3 | B13: Construction and management simulation | C13: 38261 | D13: 10
... A176: Zoo Tycoon | B176: Business simulation | C176: 37165 | D176: 1

Sheet Video game Series dataset
A1: Name | B1: Series
A2: PlayerUnknown's Battlegrounds
A3: Minecraft | B3: Minecraft
A4: Diablo III | B4: Diablo
A5: Garry's Mod
A6: Terraria
A7: World of Warcraft | B7: Warcraft
A8: Half-Life 2 | B8: Half-Life
A9: The Witcher 3: Wild Hunt | B9: The Witcher
A10: StarCraft | B10: StarCraft
A11: The Sims | B11: The Sims
A12: Fall Guys
A13: RollerCoaster Tycoon 3 | B13: RollerCoaster Tycoon
A14: Half-Life | B14: Half-Life
A15: Rust
A16: Civilization V | B16: Civilization
A17: The Sims 3 | B17: The Sims
A18: Euro Truck Simulator 2 | B18: Truck Simulator
A19: Guild Wars | B19: Guild Wars
A20: StarCraft II: Wings of Liberty | B20: StarCraft
A21: The Sims 2 | B21: The Sims
A22: Valheim
A23: ARMA 3 | B23: ARMA
A24: Last Ninja 2 | B24: The Last Ninja
A25: Cities: Skylines
A26: Guild Wars 2 | B26: Guild Wars
A27: SimCity 3000 | B27: SimCity
A28: The Forest
A29: Cyberpunk 2077
A30: DayZ
A31: Diablo II | B31: Diablo
A32: Populous | B32: Populous
A33: RollerCoaster Tycoon | B33: RollerCoaster Tycoon
A34: The Last Ninja | B34: The Last Ninja
A35: Warhammer 40,000: Dawn of War (including expansions) | B35: Warhammer
A36: Where in the World Is Carmen Sandiego? | B36: Carmen Sandiego
A37: Dark Souls | B37: Dark Souls
A38: Dark Souls III | B38: Dark Souls
A39: Age of Empires | B39: Age of Empires
A40: Civilization IV | B40: Civilization
...

Sheet Developer dataset
A1: Developer | B1: Name | C1: Series
A2: PUBG Studios | B2: PlayerUnknown's Battlegrounds
A3: Mojang Studios | B3: Minecraft | C3: Minecraft
A4: Blizzard Entertainment | B4: Diablo III | C4: Diablo
A5: Facepunch Studios | B5: Garry's Mod
A6: Re-Logic | B6: Terraria
A7: Blizzard Entertainment | B7: World of Warcraft | C7: Warcraft
A8: Valve | B8: Half-Life 2 | C8: Half-Life
A9: CD Projekt Red | B9: The Witcher 3: Wild Hunt | C9: The Witcher
A10: Blizzard Entertainment | B10: StarCraft | C10: StarCraft
A11: Maxis | B11: The Sims | C11: The Sims
A12: Mediatonic | B12: Fall Guys
A13: Frontier Developments | B13: RollerCoaster Tycoon 3 | C13: RollerCoaster Tycoon
A14: Valve | B14: Half-Life | C14: Half-Life
A15: Facepunch Studios | B15: Rust
A16: Firaxis Games | B16: Civilization V | C16: Civilization
A17: Maxis | B17: The Sims 3 | C17: The Sims
A18: SCS Software | B18: Euro Truck Simulator 2 | C18: Truck Simulator
A19: ArenaNet | B19: Guild Wars | C19: Guild Wars
A20: Blizzard Entertainment | B20: StarCraft II: Wings of Liberty | C20: StarCraft
A21: Maxis | B21: The Sims 2 | C21: The Sims
A22: Iron Gate | B22: Valheim
A23: Bohemia Interactive | B23: ARMA 3 | C23: ARMA
A24: System 3 | B24: Last Ninja 2 | C24: The Last Ninja
A25: Colossal Order | B25: Cities: Skylines
A26: ArenaNet | B26: Guild Wars 2 | C26: Guild Wars
A27: Maxis | B27: SimCity 3000 | C27: SimCity
A28: Endnight Games | B28: The Forest
A29: CD Projekt Red | B29: Cyberpunk 2077
A30: Bohemia Interactive | B30: DayZ
A31: Blizzard North | B31: Diablo II | C31: Diablo
A32: Bullfrog Productions | B32: Populous | C32: Populous
A33: Chris Sawyer | B33: RollerCoaster Tycoon | C33: RollerCoaster Tycoon
A34: System 3 | B34: The Last Ninja | C34: The Last Ninja
A35: Relic Entertainment | B35: Warhammer 40,000: Dawn of War (including expansions) | C35: Warhammer
A36: Broderbund | B36: Where in the World Is Carmen Sandiego? | C36: Carmen Sandiego
A37: FromSoftware | B37: Dark Souls | C37: Dark Souls
A38: FromSoftware | B38: Dark Souls III | C38: Dark Souls
A39: Ensemble Studios | B39: Age of Empires | C39: Age of Empires
A40: Firaxis Games | B40: Civilization IV | C40: Civilization
...
